Workbook

Sheet Summary
A1: Black-Box Test Cases: Account Creation
A2: Multi-role e-commerce system (Buyer, Seller, Logistics, Rider)
A4: Test run details
A5: System under test
A6: Version / build
A7: Test environment (browser, device)
A8: Tester
A9: Date tested
A11: Results by role
A12: Role (sheet) | B12: Total test cases | C12: Pass | D12: Fail | E12: Blocked | F12: Not Run | G12: Pass rate (Pass / Total)
A13: Buyer | B13: =COUNTA(#REF!) -> #REF! | C13: =COUNTIF(#REF!,"Pass") -> #REF! | D13: =COUNTIF(#REF!,"Fail") -> #REF! | E13: =COUNTIF(#REF!,"Blocked") -> #REF! | F13: =COUNTIF(#REF!,"Not Run") -> #REF! | G13: =IF(B13=0,0,C13/B13) -> #REF!
A14: Seller | B14: =COUNTA(#REF!) -> #REF! | C14: =COUNTIF(#REF!,"Pass") -> #REF! | D14: =COUNTIF(#REF!,"Fail") -> #REF! | E14: =COUNTIF(#REF!,"Blocked") -> #REF! | F14: =COUNTIF(#REF!,"Not Run") -> #REF! | G14: =IF(B14=0,0,C14/B14) -> #REF!
A15: Logistics | B15: =COUNTA(#REF!) -> #REF! | C15: =COUNTIF(#REF!,"Pass") -> #REF! | D15: =COUNTIF(#REF!,"Fail") -> #REF! | E15: =COUNTIF(#REF!,"Blocked") -> #REF! | F15: =COUNTIF(#REF!,"Not Run") -> #REF! | G15: =IF(B15=0,0,C15/B15) -> #REF!
A16: Rider | B16: =COUNTA(Rider!$A$2:$A$200) -> 32 | C16: =COUNTIF(Rider!$L$2:$L$200,"Pass") -> 0 | D16: =COUNTIF(Rider!$L$2:$L$200,"Fail") -> 0 | E16: =COUNTIF(Rider!$L$2:$L$200,"Blocked") -> 0 | F16: =COUNTIF(Rider!$L$2:$L$200,"Not Run") -> 32 | G16: =IF(B16=0,0,C16/B16) -> 0
A17: Total | B17: =SUM(B13:B16) -> #REF! | C17: =SUM(C13:C16) -> #REF! | D17: =SUM(D13:D16) -> #REF! | E17: =SUM(E13:E16) -> #REF! | F17: =SUM(F13:F16) -> #REF! | G17: =IF(B17=0,0,C17/B17) -> #REF!
A19: How to use this workbook
A20: 1. Read the Assumptions sheet first. The rules are modeled on Philippine marketplaces, so adjust any case whose rule differs from your system.
A21: 2. The Test Data sheet lists every form field with two ready-made accounts per role. The Test Files sheet lists the upload files to prepare. All people, companies and numbers are fictional.
A22: 3. Emails use example.com, so nothing is delivered to a real inbox. Read OTP and activation emails from a mail catcher such as Mailtrap, or from your application's mail log.
A23: 4. On each role sheet, run the Test Steps with the Test Data and compare what happens with the Expected Result. Use a spare email and mobile number from the Test Data sheet whenever a value marked (accept) creates another account.
A24: 5. Dates of birth and license expiry dates in the boundary cases are calculated from today's date, so they are always correct on the day you test.
A25: 6. Fill in only the yellow cells: Actual Result, Status and Remarks. Pick the Status from the dropdown (Pass, Fail, Blocked, Not Run).
A26: 7. Pass = actual matches expected. Fail = it does not (describe what happened and add a screenshot or bug number in Remarks). Blocked = the case could not be run, for example because an earlier case failed.
A27: 8. The Results by role table above updates automatically from the Status column.
A29: Example of a filled-in row (illustration only, not a real result)
A30: Test Case ID | B30: Test Scenario | C30: Expected Result | D30: Actual Result | E30: Status | F30: Remarks
A31: TC-BUY-010 | B31: Email that is already registered | C31: Registration is blocked. A message says the email is already in use. No account is created. | D31: No message was shown. A second account was created with juanmiguel.delacruz@example.com. | E31: Fail | F31: Bug #012. Screenshot: buy-010.png
A34: Black-box techniques used
A35: Equivalence Partitioning | B35: Inputs are grouped into valid and invalid classes, and one value from each class is tested.
A36: Boundary Value Analysis | B36: Values at and just beyond a limit are tested, for example 7 and 8 characters for a minimum of 8.
A37: Decision Table | B37: Combinations of conditions are tested, for example each missing password character type.
A38: State Transition | B38: Changes in account status are tested, for example Unverified to Active or Pending Approval to Approved.
A39: Use Case Testing | B39: A complete user flow is tested from start to finish with valid data.
A40: Error Guessing | B40: Likely mistakes are tested based on experience, for example double-clicking Register or pasting another role's URL.

Sheet Test Data
A1: Test data and input details
A2: Every form field per role, with its rule and two complete sets of valid data. Account 1 is the main account in the test cases. Account 2 is for cases that need a second account. All people, companies, numbers and addresses are fictional.
A4: Buyer: Self-registration
A5: Role | B5: Field | C5: Required | D5: Input type | E5: Format / rule | F5: Account 1 (valid) | G5: Account 2 (valid)
A6: Buyer | B6: First Name | C6: Yes | D6: Text | E6: 2 to 50 characters; letters, spaces, hyphen, apostrophe, period | F6: Juan Miguel | G6: Ana Marie
A7: Buyer | B7: Last Name | C7: Yes | D7: Text | E7: 2 to 50 characters; letters, spaces, hyphen, apostrophe, period | F7: Dela Cruz | G7: Reyes
A8: Buyer | B8: Email | C8: Yes | D8: Email | E8: Valid email format; unique | F8: juanmiguel.delacruz@example.com | G8: anamarie.reyes@example.com
A9: Buyer | B9: Mobile Number | C9: Yes | D9: Text | E9: 09XXXXXXXXX or +639XXXXXXXXX; unique | F9: 09171234567 | G9: 09173456789
A10: Buyer | B10: Date of Birth | C10: Yes | D10: Date picker | E10: At least 18 years old | F10: 05/14/1998 | G10: 11/02/2001
A11: Buyer | B11: Password | C11: Yes | D11: Password | E11: Min 8 characters; uppercase, lowercase, number, special character | F11: Mamimili@2026 | G11: Suki#2026Ana
A12: Buyer | B12: Confirm Password | C12: Yes | D12: Password | E12: Must match Password | F12: Mamimili@2026 | G12: Suki#2026Ana
A13: Buyer | B13: Terms and Privacy Policy | C13: Yes | D13: Checkbox | E13: Must be ticked | F13: Ticked | G13: Ticked
A15: Seller: Self-registration, then admin approval
A16: Role | B16: Field | C16: Required | D16: Input type | E16: Format / rule | F16: Account 1 (valid) | G16: Account 2 (valid)
A17: Seller | B17: First Name | C17: Yes | D17: Text | E17: 2 to 50 characters; letters, spaces, hyphen, apostrophe, period | F17: Maria Clara | G17: Roberto
A18: Seller | B18: Last Name | C18: Yes | D18: Text | E18: 2 to 50 characters; letters, spaces, hyphen, apostrophe, period | F18: Santos | G18: Villanueva
A19: Seller | B19: Email | C19: Yes | D19: Email | E19: Valid email format; unique | F19: mariaclara.santos@example.com | G19: roberto.villanueva@example.com
A20: Seller | B20: Mobile Number | C20: Yes | D20: Text | E20: 09XXXXXXXXX or +639XXXXXXXXX; unique | F20: 09189876543 | G20: 09194567890
A21: Seller | B21: Shop Name | C21: Yes | D21: Text | E21: 3 to 30 characters; unique | F21: Maria Clara Handicrafts | G21: RV Gadget Hub
A22: Seller | B22: Shop Category | C22: Yes | D22: Dropdown | E22: One main category | F22: Home & Living | G22: Mobiles & Gadgets
A23: Seller | B23: Seller Type | C23: Yes | D23: Dropdown | E23: Individual, Sole Proprietorship or Corporation | F23: Sole Proprietorship | G23: Corporation
A24: Seller | B24: TIN | C24: Yes | D24: Text | E24: 000-000-000-000 (12 digits); unique | F24: 123-456-789-000 | G24: 456-789-012-000
A25: Seller | B25: Region | C25: Yes | D25: Dropdown | E25: Philippine regions | F25: National Capital Region (NCR) | G25: Region VII (Central Visayas)
A26: Seller | B26: Province | C26: Yes | D26: Dropdown | E26: Filtered by Region | F26: Metro Manila | G26: Cebu
A27: Seller | B27: City / Municipality | C27: Yes | D27: Dropdown | E27: Filtered by Province | F27: Quezon City | G27: Cebu City
... A37: Seller | B37: Terms and Privacy Policy | C37: Yes | D37: Checkbox | E37: Must be ticked | F37: Ticked | G37: Ticked
A39: Logistics: Self-registration, then admin approval
A40: Role | B40: Field | C40: Required | D40: Input type | E40: Format / rule | F40: Account 1 (valid) | G40: Account 2 (valid)
A41: Logistics | B41: Company Name | C41: Yes | D41: Text | E41: Unique | F41: Bilis Hatid Express Inc. | G41: Agila Cargo Movers Corp.
A42: Logistics | B42: SEC Registration No. | C42: Yes | D42: Text | E42: 2 letters followed by 9 digits; unique | F42: CS202012345 | G42: CS201998765
A43: Logistics | B43: TIN | C43: Yes | D43: Text | E43: 000-000-000-000 (12 digits); unique | F43: 234-567-890-000 | G43: 567-890-123-000
A44: Logistics | B44: Region | C44: Yes | D44: Dropdown | E44: Philippine regions | F44: National Capital Region (NCR) | G44: Region XI (Davao Region)
A45: Logistics | B45: Province | C45: Yes | D45: Dropdown | E45: Filtered by Region | F45: Metro Manila | G45: Davao del Sur
A46: Logistics | B46: City / Municipality | C46: Yes | D46: Dropdown | E46: Filtered by Province | F46: Pasig City | G46: Davao City
A47: Logistics | B47: Barangay | C47: Yes | D47: Dropdown | E47: Filtered by City / Municipality | F47: Kapitolyo | G47: Buhangin
A48: Logistics | B48: Street Address | C48: Yes | D48: Text | E48: House, unit or lot number and street | F48: Unit 5B, 88 West Capitol Drive | G48: Door 3, 210 Sampaguita St.
A49: Logistics | B49: Postal Code | C49: Yes | D49: Text | E49: Exactly 4 digits | F49: 1603 | G49: 8000
A50: Logistics | B50: Contact Person First Name | C50: Yes | D50: Text | E50: 2 to 50 characters; letters, spaces, hyphen, apostrophe, period | F50: Carlos Antonio | G50: Liza Mae
A51: Logistics | B51: Contact Person Last Name | C51: Yes | D51: Text | E51: 2 to 50 characters; letters, spaces, hyphen, apostrophe, period | F51: Mendoza | G51: Fernandez
... A62: Logistics | B62: Terms and Privacy Policy | C62: Yes | D62: Checkbox | E62: Must be ticked | F62: Ticked | G62: Ticked
...

Sheet Test Files
A1: Upload files to prepare
A2: Prepare these files before testing the document uploads. Use sample or blank documents, not anyone's real ID or certificate. The size limit is 5 MB, which is 5,120 KB or 5,242,880 bytes.
A4: File name | B4: Type | C4: Size | D4: Used for | E4: Expected result
A5: govt_id_front.jpg | B5: JPG | C5: 1.2 MB | D5: Valid government ID | E5: Accept
A6: govt_id_front.png | B6: PNG | C6: 2.4 MB | D6: Valid government ID in PNG | E6: Accept
A7: dti_certificate.pdf | B7: PDF | C7: 850 KB | D7: DTI Certificate of Business Name Registration | E7: Accept
A8: dti_certificate_clear.pdf | B8: PDF | C8: 1.0 MB | D8: Replacement document for the resubmit test (seller) | E8: Accept
A9: sec_certificate.pdf | B9: PDF | C9: 1.0 MB | D9: SEC Certificate of Registration | E9: Accept
A10: bir_2303.pdf | B10: PDF | C10: 1.1 MB | D10: BIR Certificate of Registration (Form 2303) | E10: Accept
A11: mayors_permit.pdf | B11: PDF | C11: 1.3 MB | D11: Mayor's / Business Permit | E11: Accept
A12: mayors_permit_2026.pdf | B12: PDF | C12: 1.2 MB | D12: Replacement document for the resubmit test (logistics) | E12: Accept
A13: drivers_license.jpg | B13: JPG | C13: 1.5 MB | D13: Rider's driver's license | E13: Accept
A14: drivers_license.png | B14: PNG | C14: 2.0 MB | D14: Rider's driver's license in PNG | E14: Accept
A15: drivers_license.pdf | B15: PDF | C15: 700 KB | D15: Rider's driver's license in PDF | E15: Accept
... A22: installer.exe | B22: EXE | C22: 2.1 MB | D22: Wrong file type (program) | E22: Reject

Sheet Assumptions
A1: Assumptions used in the test cases
A2: These rules are modeled on Philippine marketplaces, not taken from your actual system. Write your real rule in column D where it differs, then filter the Assumption Ref column on each role sheet to find the test cases to adjust.
A4: Ref | B4: Topic | C4: Assumed rule | D4: Your system's actual rule (fill in if different)
A5: A1 | B5: Form fields | C5: Each role's form has the fields listed on the Test Data sheet, modeled on Philippine marketplaces. Payout details (bank or e-wallet) are set up after approval, not during registration.
A6: A2 | B6: Name rule | C6: 2 to 50 characters. Letters (including ñ), spaces, hyphen, apostrophe and period only.
A7: A3 | B7: Email rule | C7: Must be a valid email format. Unique across all roles (one email = one account). Not case-sensitive. Leading and trailing spaces are removed.
A8: A4 | B8: Mobile number rule | C8: Philippine mobile number entered as 09XXXXXXXXX (11 digits) or +639XXXXXXXXX. Both forms are stored as the same number. Unique across all accounts.
A9: A5 | B9: Password rule | C9: At least 8 characters with at least one uppercase letter, one lowercase letter, one number and one special character. Confirm Password must match.
A10: A6 | B10: Date of birth rule | C10: Buyers and riders must be at least 18 years old on the day of registration. A future date is not allowed.
A11: A7 | B11: Address rule | C11: Region, Province, City/Municipality and Barangay are linked dropdowns: each list depends on the one before it. Postal Code is exactly 4 digits.
A12: A8 | B12: TIN rule | C12: 12 digits in the form 000-000-000-000 (9-digit TIN plus 3-digit branch code). Unique across seller and logistics accounts.
A13: A9 | B13: Email verification (OTP) | C13: A 6-digit numeric code is emailed after registration. It is valid for 5 minutes. Resending creates a new code and cancels the old one. An account cannot be used until it is verified.
A14: A10 | B14: Document upload rule | C14: Accepted file types: JPG, PNG, PDF. Maximum size: 5 MB (5,120 KB) per file.
A15: A11 | B15: Seller documents by seller type | C15: Individual: Government-issued ID. Sole Proprietorship: Government-issued ID, DTI Certificate and BIR Form 2303. Corporation: Government-issued ID of the representative, SEC Certificate and BIR Form 2303.
A16: A12 | B16: Account status flow | C16: Buyer: Unverified, then Active after OTP. Seller and Logistics: Unverified, then Pending Approval after OTP, then Approved or Rejected by an admin. A rejected applicant can correct the details and resubmit.
... A20: A16 | B20: Role-based access | C20: Each role can open only its own pages. Opening another role's page is denied (error 403 or redirect).

Sheet Rider
A1: Test Case ID | B1: Module | C1: Test Scenario | D1: Technique | E1: Priority | F1: Preconditions | G1: Test Steps | H1: Test Data | I1: Expected Result | J1: Assumption Ref | K1: Actual Result | L1: Status | M1: Remarks
A2: TC-RID-001 | B2: Add Rider Form | C2: Create a rider with all valid data | D2: Use Case Testing | E2: High | F2: The Approved logistics account operations@bilishatid.example.com is logged in and the Add Rider form is open. The email, mobile number, license number and plate number in the test data are not yet registered. | G2: 1. Fill in every field with the test data. 2. Click Save. | H2: First Name: Pedro Jose Last Name: Garcia Date of Birth: 03/22/1995 Email: pedrojose.garcia@example.com Mobile Number: 09451239876 Driver's License No.: N01-23-456789 License Expiry Date: 03/22/2030 Vehicle Type: Motorcycle Plate Number: 123ABC Driver's License (upload): drivers_license.jpg (1.5 MB) Vehicle OR/CR (upload): or_cr.pdf (900 KB) | I2: The rider is saved with no validation errors and appears in the rider list of Bilis Hatid Express Inc. with status Pending Activation. An activation email is sent to pedrojose.garcia@example.com. | J2: A1, A13 | K2: Created rider from logistics form, read local logged invitation, activated, signed in, verified single-use link and denied public registration. External email delivery unverified. | L2: PARTIAL | M2: NOT CERTIFIED. PARTIAL: Created rider from logistics form, read local logged invitation, activated, signed in, verified single-use link and denied public registration. External email delivery unverified. Evidence: regression-final.xml: Tests.Feature.TeacherRiderInvitationTest::test_tc_rid_001_valid_rider_is_created_once_with_documents_and_email_invitation; rider-invitation-browser.json
A3: TC-RID-002 | B3: Required Fields | C3: Submit a completely empty form | D3: Equivalence Partitioning | E3: High | F3: The Approved logistics account operations@bilishatid.example.com is logged in and the Add Rider form is open. | G3: 1. Leave every field blank and every dropdown on its default option. 2. Click Save. | H3: All fields blank | I3: Saving is blocked. A required-field message is shown for every mandatory field. No rider is created and no email is sent. | J3: A1 | K3: Related HTTP/database assertions passed on isolated SQLite fixtures. Full workbook UI steps and all stated data variants are not certified by this result. | L3: PARTIAL | M3: NOT CERTIFIED. PARTIAL: Related HTTP/database assertions passed on isolated SQLite fixtures. Full workbook UI steps and all stated data variants are not certified by this result. Evidence: regression-final.xml: Tests.Feature.TeacherRiderInvitationTest::test_tc_rid_002_003_all_required_fields_must_be_present
A4: TC-RID-003 | B4: Required Fields | C4: Leave one required field blank at a time | D4: Equivalence Partitioning | E4: High | F4: The Approved logistics account operations@bilishatid.example.com is logged in and the Add Rider form is open. | G4: 1. Fill in all fields with valid data. 2. Clear one required field. 3. Click Save. 4. Repeat for each field in the test data. | H4: Clear in turn: First Name Last Name Date of Birth Email Mobile Number Driver's License No. License Expiry Date Vehicle Type Plate Number Driver's License (upload) Vehicle OR/CR (upload) | I4: Each time, saving is blocked and a required-field message is shown on the blank field only. Other entered values (except uploads) are kept. No rider is created. | J4: A1 | K4: Related HTTP/database assertions passed on isolated SQLite fixtures. Full workbook UI steps and all stated data variants are not certified by this result. | L4: PARTIAL | M4: NOT CERTIFIED. PARTIAL: Related HTTP/database assertions passed on isolated SQLite fixtures. Full workbook UI steps and all stated data variants are not certified by this result. Evidence: regression-final.xml: Tests.Feature.TeacherRiderInvitationTest::test_tc_rid_002_003_all_required_fields_must_be_present
A5: TC-RID-004 | B5: Name | C5: Name with numbers or symbols | D5: Equivalence Partitioning | E5: Medium | F5: The Approved logistics account operations@bilishatid.example.com is logged in and the Add Rider form is open. | G5: 1. Fill in all other fields with valid data. 2. Enter the test data in the name fields. 3. Click Save. | H5: First Name: Pedro Jose99 Last Name: Dela Cruz@# | I5: Saving is blocked. A message on each name field says only letters are allowed. | J5: A2 | K5: Related HTTP/database assertions passed on isolated SQLite fixtures. Full workbook UI steps and all stated data variants are not certified by this result. | L5: PARTIAL | M5: NOT CERTIFIED. PARTIAL: Related HTTP/database assertions passed on isolated SQLite fixtures. Full workbook UI steps and all stated data variants are not certified by this result. Evidence: regression-final.xml: Tests.Feature.TeacherRiderInvitationTest::test_tc_rid_004_005_name_format_and_length
A6: TC-RID-005 | B6: Name | C6: Name length at the limits | D6: Boundary Value Analysis | E6: Medium | F6: The Approved logistics account operations@bilishatid.example.com is logged in and the Add Rider form is open. The email, mobile number, license number and plate number in the test data are not yet registered. | G6: 1. Fill in all other fields with valid data. 2. Enter each first name in the test data, one per attempt. 3. Click Save. | H6: 1 character: P (reject) 2 characters: Po (accept) 50 characters: Maria Cristina Angelica Bernadette Josefina Leonor (accept) 51 characters: Maria Cristina Angelica Bernadette Josefina Leonora (reject) | I6: 1 and 51 characters are rejected with a length message. 2 and 50 characters are accepted. | J6: A2 | K6: Related HTTP/database assertions passed on isolated SQLite fixtures. Full workbook UI steps and all stated data variants are not certified by this result. | L6: PARTIAL | M6: NOT CERTIFIED. PARTIAL: Related HTTP/database assertions passed on isolated SQLite fixtures. Full workbook UI steps and all stated data variants are not certified by this result. Evidence: regression-final.xml: Tests.Feature.TeacherRiderInvitationTest::test_tc_rid_004_005_name_format_and_length
A7: TC-RID-006 | B7: Date of Birth | C7: Age at the 18-year limit | D7: Boundary Value Analysis | E7: High | F7: The Approved logistics account operations@bilishatid.example.com is logged in and the Add Rider form is open. The email, mobile number, license number and plate number in the test data are not yet registered. | G7: 1. Fill in all other fields with valid data. 2. Enter each date of birth in the test data, one per attempt. 3. Click Save. | H7: ="Born "&TEXT(EDATE(TODAY(),-216)+1,"mm/dd/yyyy")&" (17 years old, reject)"&CHAR(10)&"Born "&TEXT(EDATE(TODAY(),-216),"mm/dd/yyyy")&" (turns 18 today, accept)"&CHAR(10)&"Born "&TEXT(EDATE(TODAY(),-216)-1,"mm/dd/yyyy")&" (18 years and 1 day, accept)" -> Born 10/17/2008 (17 years old, reject) Born 10/16/2008 (turns 18 today, accept) Born 10/15/2008 (18 years and 1 day, accept) | I7: The 17-year-old date is rejected with a message that the person must be at least 18. The other two dates are accepted. | J7: A6 | K7: Related HTTP/database assertions passed on isolated SQLite fixtures. Full workbook UI steps and all stated data variants are not certified by this result. | L7: PARTIAL | M7: NOT CERTIFIED. PARTIAL: Related HTTP/database assertions passed on isolated SQLite fixtures. Full workbook UI steps and all stated data variants are not certified by this result. Evidence: regression-final.xml: Tests.Feature.TeacherRiderInvitationTest::test_tc_rid_006_age_boundary
A8: TC-RID-007 | B8: Email | C8: Email in an invalid format | D8: Equivalence Partitioning | E8: High | F8: The Approved logistics account operations@bilishatid.example.com is logged in and the Add Rider form is open. | G8: 1. Fill in all other fields with valid data. 2. Enter each email in the test data, one per attempt. 3. Click Save. | H8: pedrojose.garciaexample.com (no @) pedrojose.garcia@ (no domain) @example.com (no name) pedrojose.garcia@example (no .com) pedrojose garcia@example.com (space) | I8: Each value is rejected with a message asking for a valid email address. No rider is created. | J8: A3 | K8: Related HTTP/database assertions passed on isolated SQLite fixtures. Full workbook UI steps and all stated data variants are not certified by this result. | L8: PARTIAL | M8: NOT CERTIFIED. PARTIAL: Related HTTP/database assertions passed on isolated SQLite fixtures. Full workbook UI steps and all stated data variants are not certified by this result. Evidence: regression-final.xml: Tests.Feature.TeacherRiderInvitationTest::test_tc_rid_007_008_email_format_and_cross_role_uniqueness
A9: TC-RID-008 | B9: Email | C9: Email already used by an account of another role | D9: Equivalence Partitioning | E9: High | F9: The Approved logistics account operations@bilishatid.example.com is logged in and the Add Rider form is open. The buyer account juanmiguel.delacruz@example.com already exists. | G9: 1. Fill in all other fields with valid data. 2. Enter the existing email. 3. Click Save. | H9: Email: juanmiguel.delacruz@example.com | I9: Saving is blocked. A message says the email is already in use. No rider is created. | J9: A3 | K9: Related HTTP/database assertions passed on isolated SQLite fixtures. Full workbook UI steps and all stated data variants are not certified by this result. | L9: PARTIAL | M9: NOT CERTIFIED. PARTIAL: Related HTTP/database assertions passed on isolated SQLite fixtures. Full workbook UI steps and all stated data variants are not certified by this result. Evidence: regression-final.xml: Tests.Feature.TeacherRiderInvitationTest::test_tc_rid_007_008_email_format_and_cross_role_uniqueness
A10: TC-RID-009 | B10: Mobile Number | C10: Mobile number in an invalid format | D10: Equivalence Partitioning | E10: High | F10: The Approved logistics account operations@bilishatid.example.com is logged in and the Add Rider form is open. | G10: 1. Fill in all other fields with valid data. 2. Enter each mobile number in the test data, one per attempt. 3. Click Save. | H10: 0917ABC4567 (letters) 0917-123-456 (symbols, too short) 12345678901 (does not start with 09) 02-8123-4567 (landline) | I10: Each value is rejected with a message asking for a valid mobile number. | J10: A4 | K10: Related HTTP/database assertions passed on isolated SQLite fixtures. Full workbook UI steps and all stated data variants are not certified by this result. | L10: PARTIAL | M10: NOT CERTIFIED. PARTIAL: Related HTTP/database assertions passed on isolated SQLite fixtures. Full workbook UI steps and all stated data variants are not certified by this result. Evidence: regression-final.xml: Tests.Feature.TeacherRiderInvitationTest::test_tc_rid_009_010_011_mobile_formats_and_duplicate_normalization
A11: TC-RID-010 | B11: Mobile Number | C11: Mobile number length at the limits | D11: Boundary Value Analysis | E11: High | F11: The Approved logistics account operations@bilishatid.example.com is logged in and the Add Rider form is open. The email, mobile number, license number and plate number in the test data are not yet registered. | G11: 1. Fill in all other fields with valid data. 2. Enter each mobile number in the test data, one per attempt. 3. Click Save. | H11: 10 digits: 0917123456 (reject) 11 digits: 09170000001 (accept) 12 digits: 091712345678 (reject) | I11: 10 and 12 digits are rejected with a length message. 11 digits is accepted. | J11: A4 | K11: Related HTTP/database assertions passed on isolated SQLite fixtures. Full workbook UI steps and all stated data variants are not certified by this result. | L11: PARTIAL | M11: NOT CERTIFIED. PARTIAL: Related HTTP/database assertions passed on isolated SQLite fixtures. Full workbook UI steps and all stated data variants are not certified by this result. Evidence: regression-final.xml: Tests.Feature.TeacherRiderInvitationTest::test_tc_rid_009_010_011_mobile_formats_and_duplicate_normalization
A12: TC-RID-011 | B12: Mobile Number | C12: Mobile number that is already registered | D12: Equivalence Partitioning | E12: Medium | F12: The Approved logistics account operations@bilishatid.example.com is logged in and the Add Rider form is open. An account already exists with mobile number 09171234567. | G12: 1. Fill in all other fields with valid data. 2. Enter the existing mobile number. 3. Click Save. | H12: Mobile: 09171234567 | I12: Saving is blocked. A message says the mobile number is already in use. | J12: A4 | K12: Related HTTP/database assertions passed on isolated SQLite fixtures. Full workbook UI steps and all stated data variants are not certified by this result. | L12: PARTIAL | M12: NOT CERTIFIED. PARTIAL: Related HTTP/database assertions passed on isolated SQLite fixtures. Full workbook UI steps and all stated data variants are not certified by this result. Evidence: regression-final.xml: Tests.Feature.TeacherRiderInvitationTest::test_tc_rid_009_010_011_mobile_formats_and_duplicate_normalization
A13: TC-RID-012 | B13: License and Vehicle | C13: Driver's license number in an invalid format | D13: Equivalence Partitioning | E13: High | F13: The Approved logistics account operations@bilishatid.example.com is logged in and the Add Rider form is open. | G13: 1. Fill in all other fields with valid data. 2. Enter each license number in the test data, one per attempt. 3. Click Save. | H13: N01-23-45678 (one digit short) N01-23-4567890 (one digit extra) 101-23-456789 (no letter) N0123456789X (letter at the end) | I13: Each value is rejected with a message showing the format A00-00-000000. | J13: A15 | K13: Related HTTP/database assertions passed on isolated SQLite fixtures. Full workbook UI steps and all stated data variants are not certified by this result. | L13: PARTIAL | M13: NOT CERTIFIED. PARTIAL: Related HTTP/database assertions passed on isolated SQLite fixtures. Full workbook UI steps and all stated data variants are not certified by this result. Evidence: regression-final.xml: Tests.Feature.TeacherRiderInvitationTest::test_tc_rid_012_013_014_015_license_format_expiry_and_unique_identifiers
A14: TC-RID-013 | B14: License and Vehicle | C14: Driver's license number already registered | D14: Equivalence Partitioning | E14: High | F14: The Approved logistics account operations@bilishatid.example.com is logged in and the Add Rider form is open. The rider pedrojose.garcia@example.com already exists. | G14: 1. Fill in all other fields with valid data. 2. Enter the existing license number. 3. Click Save. | H14: Driver's License No.: N01-23-456789 | I14: Saving is blocked. A message says the license number is already registered. | J14: A14 | K14: Related HTTP/database assertions passed on isolated SQLite fixtures. Full workbook UI steps and all stated data variants are not certified by this result. | L14: PARTIAL | M14: NOT CERTIFIED. PARTIAL: Related HTTP/database assertions passed on isolated SQLite fixtures. Full workbook UI steps and all stated data variants are not certified by this result. Evidence: regression-final.xml: Tests.Feature.TeacherRiderInvitationTest::test_tc_rid_012_013_014_015_license_format_expiry_and_unique_identifiers
A15: TC-RID-014 | B15: License and Vehicle | C15: License expiry date at the limit | D15: Boundary Value Analysis | E15: High | F15: The Approved logistics account operations@bilishatid.example.com is logged in and the Add Rider form is open. The email, mobile number, license number and plate number in the test data are not yet registered. | G15: 1. Fill in all other fields with valid data. 2. Enter each expiry date in the test data, one per attempt. 3. Click Save. | H15: ="Expiry "&TEXT(TODAY()-1,"mm/dd/yyyy")&" (yesterday, reject)"&CHAR(10)&"Expiry "&TEXT(TODAY(),"mm/dd/yyyy")&" (today, accept)"&CHAR(10)&"Expiry "&TEXT(TODAY()+1,"mm/dd/yyyy")&" (tomorrow, accept)" -> Expiry 10/15/2026 (yesterday, reject) Expiry 10/16/2026 (today, accept) Expiry 10/17/2026 (tomorrow, accept) | I15: Yesterday's date is rejected with a message that the license is expired. Today's and tomorrow's dates are accepted. | J15: A15 | K15: Related HTTP/database assertions passed on isolated SQLite fixtures. Full workbook UI steps and all stated data variants are not certified by this result. | L15: PARTIAL | M15: NOT CERTIFIED. PARTIAL: Related HTTP/database assertions passed on isolated SQLite fixtures. Full workbook UI steps and all stated data variants are not certified by this result. Evidence: regression-final.xml: Tests.Feature.TeacherRiderInvitationTest::test_tc_rid_012_013_014_015_license_format_expiry_and_unique_identifiers
A16: TC-RID-015 | B16: License and Vehicle | C16: Plate number already registered | D16: Equivalence Partitioning | E16: Medium | F16: The Approved logistics account operations@bilishatid.example.com is logged in and the Add Rider form is open. The rider pedrojose.garcia@example.com already exists. | G16: 1. Fill in all other fields with valid data. 2. Enter the existing plate number. 3. Click Save. | H16: Plate Number: 123ABC | I16: Saving is blocked. A message says the plate number is already registered. | J16: A14 | K16: Related HTTP/database assertions passed on isolated SQLite fixtures. Full workbook UI steps and all stated data variants are not certified by this result. | L16: PARTIAL | M16: NOT CERTIFIED. PARTIAL: Related HTTP/database assertions passed on isolated SQLite fixtures. Full workbook UI steps and all stated data variants are not certified by this result. Evidence: regression-final.xml: Tests.Feature.TeacherRiderInvitationTest::test_tc_rid_012_013_014_015_license_format_expiry_and_unique_identifiers
A17: TC-RID-016 | B17: Document Upload | C17: Upload documents in each accepted file type | D17: Equivalence Partitioning | E17: High | F17: The Approved logistics account operations@bilishatid.example.com is logged in and the Add Rider form is open. The email, mobile number, license number and plate number in the test data are not yet registered. | G17: 1. Fill in all other fields with valid data. 2. Upload the files in the test data. 3. Click Save. | H17: Driver's License: drivers_license.jpg (1.5 MB), then drivers_license.png (2.0 MB), then drivers_license.pdf (700 KB) Vehicle OR/CR: or_cr.pdf (900 KB) | I17: Each file is accepted and its name or preview is shown. The rider is saved. | J17: A10 | K17: No complete execution of this workbook scenario has been recorded. | L17: UNVERIFIED | M17: NOT CERTIFIED. UNVERIFIED: No complete execution of this workbook scenario has been recorded. Evidence: No completed execution evidence.
A18: TC-RID-017 | B18: Document Upload | C18: Upload a file type that is not accepted | D18: Equivalence Partitioning | E18: High | F18: The Approved logistics account operations@bilishatid.example.com is logged in and the Add Rider form is open. | G18: 1. Fill in all other fields with valid data. 2. Try to upload each file in the test data to Driver's License, one per attempt. 3. Click Save. | H18: price_list.docx (320 KB) store_banner.gif (480 KB) installer.exe (2.1 MB) | I18: Each file is rejected with a message listing the accepted types (JPG, PNG, PDF). No rider is created. | J18: A10 | K18: Related HTTP/database assertions passed on isolated SQLite fixtures. Full workbook UI steps and all stated data variants are not certified by this result. | L18: PARTIAL | M18: NOT CERTIFIED. PARTIAL: Related HTTP/database assertions passed on isolated SQLite fixtures. Full workbook UI steps and all stated data variants are not certified by this result. Evidence: regression-final.xml: Tests.Feature.TeacherRiderInvitationTest::test_tc_rid_017_018_upload_content_and_size_boundaries
A19: TC-RID-018 | B19: Document Upload | C19: File size at the limit | D19: Boundary Value Analysis | E19: High | F19: The Approved logistics account operations@bilishatid.example.com is logged in and the Add Rider form is open. The email, mobile number, license number and plate number in the test data are not yet registered. | G19: 1. Fill in all other fields with valid data. 2. Upload each file in the test data to Driver's License, one per attempt. 3. Click Save. | H19: size_4.9MB.jpg (accept) size_5.0MB.jpg, exactly 5,120 KB (accept) size_5.1MB.jpg (reject) | I19: The 4.9 MB and 5.0 MB files are accepted. The 5.1 MB file is rejected with a maximum-size message. | J19: A10 | K19: Related HTTP/database assertions passed on isolated SQLite fixtures. Full workbook UI steps and all stated data variants are not certified by this result. | L19: PARTIAL | M19: NOT CERTIFIED. PARTIAL: Related HTTP/database assertions passed on isolated SQLite fixtures. Full workbook UI steps and all stated data variants are not certified by this result. Evidence: regression-final.xml: Tests.Feature.TeacherRiderInvitationTest::test_tc_rid_017_018_upload_content_and_size_boundaries
A20: TC-RID-019 | B20: Add Rider Form | C20: Click Save several times quickly | D20: Error Guessing | E20: Medium | F20: The Approved logistics account operations@bilishatid.example.com is logged in and the Add Rider form is open. The email, mobile number, license number and plate number in the test data are not yet registered. | G20: 1. Fill in all fields with the Account 2 data from the Test Data sheet. 2. Click Save three times in quick succession. | H20: Account 2 data (Test Data sheet, column G) | I20: Only one rider is created and only one activation email is sent. | J20: A3 | K20: Related HTTP/database assertions passed on isolated SQLite fixtures. Full workbook UI steps and all stated data variants are not certified by this result. | L20: PARTIAL | M20: NOT CERTIFIED. PARTIAL: Related HTTP/database assertions passed on isolated SQLite fixtures. Full workbook UI steps and all stated data variants are not certified by this result. Evidence: regression-final.xml: Tests.Feature.TeacherRiderInvitationTest::test_tc_rid_019_multiple_save_requests_create_only_one_rider_and_invitation
A21: TC-RID-020 | B21: Account Activation | C21: Rider activates the account with a valid password | D21: State Transition | E21: High | F21: The rider pedrojose.garcia@example.com has status Pending Activation and the activation email has been read from the mail catcher. | G21: 1. Open the activation link from the email within 24 hours. 2. Enter and confirm the password. 3. Click Activate. | H21: Password: Rider@2026 Confirm Password: Rider@2026 | I21: The password is saved. The rider's status changes from Pending Activation to Active, and the login page opens with a success message. | J21: A5, A13 | K21: Created rider from logistics form, read local logged invitation, activated, signed in, verified single-use link and denied public registration. External email delivery unverified. | L21: PARTIAL | M21: NOT CERTIFIED. PARTIAL: Created rider from logistics form, read local logged invitation, activated, signed in, verified single-use link and denied public registration. External email delivery unverified. Evidence: regression-final.xml: Tests.Feature.TeacherRiderInvitationTest::test_tc_rid_020_025_026_027_activation_login_and_single_use; rider-invitation-browser.json
A22: TC-RID-021 | B22: Account Activation | C22: Set a password that breaks the password rule | D22: Decision Table | E22: High | F22: The rider pedrojose.garcia@example.com has status Pending Activation and the activation email has been read from the mail catcher. | G22: 1. Open the activation link. 2. Enter each password in both fields, one per attempt. 3. Click Activate. | H22: 7 characters: Ride@26 No uppercase: rider@2026 No lowercase: RIDER@2026 No number: Rider@abcd No special character: Rider2026 | I22: Each password is rejected with a message stating the password rule. The rider stays Pending Activation. | J22: A5 | K22: Related HTTP/database assertions passed on isolated SQLite fixtures. Full workbook UI steps and all stated data variants are not certified by this result. | L22: PARTIAL | M22: NOT CERTIFIED. PARTIAL: Related HTTP/database assertions passed on isolated SQLite fixtures. Full workbook UI steps and all stated data variants are not certified by this result. Evidence: regression-final.xml: Tests.Feature.TeacherRiderInvitationTest::test_tc_rid_021_022_password_rules_and_confirmation
A23: TC-RID-022 | B23: Account Activation | C23: Confirm Password does not match | D23: Equivalence Partitioning | E23: Medium | F23: The rider pedrojose.garcia@example.com has status Pending Activation and the activation email has been read from the mail catcher. | G23: 1. Open the activation link. 2. Enter the test data in Password and Confirm Password. 3. Click Activate. | H23: Password: Rider@2026 Confirm Password: Rider@2027 | I23: Activation is blocked. A message says the passwords do not match. | J23: A5 | K23: Related HTTP/database assertions passed on isolated SQLite fixtures. Full workbook UI steps and all stated data variants are not certified by this result. | L23: PARTIAL | M23: NOT CERTIFIED. PARTIAL: Related HTTP/database assertions passed on isolated SQLite fixtures. Full workbook UI steps and all stated data variants are not certified by this result. Evidence: regression-final.xml: Tests.Feature.TeacherRiderInvitationTest::test_tc_rid_021_022_password_rules_and_confirmation
A24: TC-RID-023 | B24: Account Activation | C24: Open an expired activation link | D24: Boundary Value Analysis | E24: High | F24: The rider pedrojose.garcia@example.com has status Pending Activation and the activation email has been read from the mail catcher. | G24: 1. Wait until more than 24 hours have passed since the email was sent (or set the link's expiry time back in the test database). 2. Open the activation link. | H24: Activation link sent 24 hours and 1 minute ago | I24: A message says the link has expired. No password can be set and the rider stays Pending Activation. | J24: A13 | K24: Related HTTP/database assertions passed on isolated SQLite fixtures. Full workbook UI steps and all stated data variants are not certified by this result. | L24: PARTIAL | M24: NOT CERTIFIED. PARTIAL: Related HTTP/database assertions passed on isolated SQLite fixtures. Full workbook UI steps and all stated data variants are not certified by this result. Evidence: regression-final.xml: Tests.Feature.TeacherRiderInvitationTest::test_tc_rid_023_024_expiry_and_resend_invalidates_old_invitation
A25: TC-RID-024 | B25: Account Activation | C25: Logistics resends the activation email | D25: State Transition | E25: Medium | F25: The rider pedrojose.garcia@example.com has status Pending Activation. The logistics account operations@bilishatid.example.com is logged in. | G25: 1. Open the rider list. 2. Click Resend Activation for Pedro Jose Garcia. 3. Open the first link. 4. Open the second link. | H25: First activation link, then the link from the second email | I25: A new activation email is sent. The first link no longer works. The second link opens the set-password page. | J25: A13 | K25: Related HTTP/database assertions passed on isolated SQLite fixtures. Full workbook UI steps and all stated data variants are not certified by this result. | L25: PARTIAL | M25: NOT CERTIFIED. PARTIAL: Related HTTP/database assertions passed on isolated SQLite fixtures. Full workbook UI steps and all stated data variants are not certified by this result. Evidence: regression-final.xml: Tests.Feature.TeacherRiderInvitationTest::test_tc_rid_023_024_expiry_and_resend_invalidates_old_invitation
A26: TC-RID-025 | B26: Account Activation | C26: Reuse the activation link after activating | D26: State Transition | E26: Medium | F26: The rider pedrojose.garcia@example.com is already Active. | G26: 1. Open the activation link that was already used. | H26: Activation link from the email that was used to activate | I26: A message says the link is invalid or already used. The password cannot be changed through this link. | J26: A13 | K26: Created rider from logistics form, read local logged invitation, activated, signed in, verified single-use link and denied public registration. External email delivery unverified. | L26: PARTIAL | M26: NOT CERTIFIED. PARTIAL: Created rider from logistics form, read local logged invitation, activated, signed in, verified single-use link and denied public registration. External email delivery unverified. Evidence: regression-final.xml: Tests.Feature.TeacherRiderInvitationTest::test_tc_rid_020_025_026_027_activation_login_and_single_use; rider-invitation-browser.json
A27: TC-RID-026 | B27: Account Activation | C27: Rider logs in before activating | D27: State Transition | E27: High | F27: The rider pedrojose.garcia@example.com has status Pending Activation. | G27: 1. Open the login page. 2. Enter the email and password. 3. Click Log In. | H27: Email: pedrojose.garcia@example.com Password: Rider@2026 | I27: Login is denied. The rider is not given access to any page. | J27: A13 | K27: Related HTTP/database assertions passed on isolated SQLite fixtures. Full workbook UI steps and all stated data variants are not certified by this result. | L27: PARTIAL | M27: NOT CERTIFIED. PARTIAL: Related HTTP/database assertions passed on isolated SQLite fixtures. Full workbook UI steps and all stated data variants are not certified by this result. Evidence: regression-final.xml: Tests.Feature.TeacherRiderInvitationTest::test_tc_rid_020_025_026_027_activation_login_and_single_use
... A33: TC-RID-032 | B33: Access Control | C33: Open another role's pages | D33: Error Guessing | E33: Medium | F33: The Active rider account pedrojose.garcia@example.com is logged in. | G33: 1. Paste the address of each dashboard in the test data into the browser, one at a time. | H33: Logistics dashboard Seller dashboard Admin dashboard | I33: Access is denied each time (error 403 or redirect). No data from the other role is shown. | J33: A16 | K33: No complete execution of this workbook scenario has been recorded. | L33: UNVERIFIED | M33: NOT CERTIFIED. UNVERIFIED: No complete execution of this workbook scenario has been recorded. Evidence: No completed execution evidence.
